Workbook
Name CategoriaTreeMap_abr: OFFSET('4'!$TR$2,0,0,COUNTA(_xlfn.ANCHORARRAY('4'!$TR$2)),2)
Name CategoriaTreeMap_ago: OFFSET('8'!$TR$2,0,0,COUNTA(_xlfn.ANCHORARRAY('8'!$TR$2)),2)
Name CategoriaTreeMap_dez: OFFSET('12'!$TR$2,0,0,COUNTA(_xlfn.ANCHORARRAY('12'!$TR$2)),2)
Name CategoriaTreeMap_fev: OFFSET('2'!#REF!,0,0,COUNTA(_xlfn.ANCHORARRAY('2'!#REF!)),2)
Name CategoriaTreeMap_jan: OFFSET('1'!#REF!,0,0,COUNTA(_xlfn.ANCHORARRAY('1'!#REF!)),2)
Name CategoriaTreeMap_jul: OFFSET('7'!$TR$2,0,0,COUNTA(_xlfn.ANCHORARRAY('7'!$TR$2)),2)
Name CategoriaTreeMap_jun: OFFSET('6'!$TR$2,0,0,COUNTA(_xlfn.ANCHORARRAY('6'!$TR$2)),2)
Name CategoriaTreeMap_mai: OFFSET('5'!$TR$2,0,0,COUNTA(_xlfn.ANCHORARRAY('5'!$TR$2)),2)
Name CategoriaTreeMap_mar: OFFSET('3'!#REF!,0,0,COUNTA(_xlfn.ANCHORARRAY('3'!#REF!)),2)
Name CategoriaTreeMap_nov: OFFSET('11'!$TR$2,0,0,COUNTA(_xlfn.ANCHORARRAY('11'!$TR$2)),2)
Name CategoriaTreeMap_out: OFFSET('10'!$TR$2,0,0,COUNTA(_xlfn.ANCHORARRAY('10'!$TR$2)),2)
Name CategoriaTreeMap_set: OFFSET('9'!$TR$2,0,0,COUNTA(_xlfn.ANCHORARRAY('9'!$TR$2)),2)
Name Filtro_Desp: TabelaDesp[Despesas]
Name Filtro_Desp: TabelaDesp[Despesas]
Name Filtro_Pag: TabelaPag[Método Pagamento]
Name Filtro_Pag: TabelaPag[Método Pagamento]
Name Produtos: TabelaProd[Produtos]
Name Produtos: TabelaProd[Produtos]
Name Serviços: TabelaServ[Serviços]
Name Serviços: TabelaServ[Serviços]
Name ValoresTreeMap_abr: OFFSET('4'!$TT$2,0,0,COUNTA(_xlfn.ANCHORARRAY('4'!$TT$2)),1)
Name ValoresTreeMap_ago: OFFSET('8'!$TT$2,0,0,COUNTA(_xlfn.ANCHORARRAY('8'!$TT$2)),1)
Name ValoresTreeMap_dez: OFFSET('12'!$TT$2,0,0,COUNTA(_xlfn.ANCHORARRAY('12'!$TT$2)),1)
Name ValoresTreeMap_fev: OFFSET('2'!#REF!,0,0,COUNTA(_xlfn.ANCHORARRAY('2'!#REF!)),1)
Name ValoresTreeMap_jan: OFFSET('1'!#REF!,0,0,COUNTA(_xlfn.ANCHORARRAY('1'!#REF!)),1)
Name ValoresTreeMap_jul: OFFSET('7'!$TT$2,0,0,COUNTA(_xlfn.ANCHORARRAY('7'!$TT$2)),1)
Name ValoresTreeMap_jun: OFFSET('6'!$TT$2,0,0,COUNTA(_xlfn.ANCHORARRAY('6'!$TT$2)),1)
Name ValoresTreeMap_mai: OFFSET('5'!$TT$2,0,0,COUNTA(_xlfn.ANCHORARRAY('5'!$TT$2)),1)
Name ValoresTreeMap_mar: OFFSET('3'!#REF!,0,0,COUNTA(_xlfn.ANCHORARRAY('3'!#REF!)),1)
Name ValoresTreeMap_nov: OFFSET('11'!$TT$2,0,0,COUNTA(_xlfn.ANCHORARRAY('11'!$TT$2)),1)
Name ValoresTreeMap_out: OFFSET('10'!$TT$2,0,0,COUNTA(_xlfn.ANCHORARRAY('10'!$TT$2)),1)
Name ValoresTreeMap_set: OFFSET('9'!$TT$2,0,0,COUNTA(_xlfn.ANCHORARRAY('9'!$TT$2)),1)

Sheet Painel
A32: ® Este material encontra-se protegido e todos os direitos reservados à Jessica & Brandão, Lda, empresa detida por Jéssica Ferreira Brandão.
A33: Qual cópia ou distribuição deste documento não autorizada, pode ser sujeita a infrações legais.

Sheet Dados
A1: Registo Dados | J1: gestorjb | L1: Despesas
L2: Despesas Fixas
L3: Despesas Variáveis
B4: Nome | C4: Bárbara Mello Carvalho | F4: Serviços | H4: Método Pagamento | L4: Investimento
B5: NIF | C5: 217663923 | F5: qEEG | H5: MBWay
B6: NISS | C6: 12036056034 | F6: NFB | H6: Transferência Bancária
B7: Senha das Finanças | C7: BARBARA25082015 | F7: Pack NFB | H7: Débito direto
B8: Senha da Segurança Social | C8: Barbara121994@ | H8: Numerário
B9: CAE/CIRS | C9: 86906 | H9: Multibanco
B10: Inicio de Atividade | C10: 45572 | F10: Produtos | H10: Pag serviços
B11: Enquadramento Contabilidade | C11: Reg. Simplificado
B12: Enquadramento de IVA | C12: IVA Trimestral
B13: Enquadramento SS | C13: Trimestral

Sheet Auxiliar1
A1: Parâmetros
C4: Dia | H4: Enquadramento Contabilidade | J4: Enquadramento de IVA | L4: Enquadramento SS
B5: 1º Entrega declaração Trimestral: | C5: 45412 | H5: Regime Simplificado | J5: Isenção Art 9º | L5: Trimestral
B6: 2º Entrega declaração Trimestral: | C6: 45504 | H6: Contabilidade Organizada | J6: Isenção Art 53º | L6: Isenção
B7: 3º Entrega declaração Trimestral: | C7: 45596 | J7: IVA Trimestral | L7: TCO
B8: 4º Entrega declaração Trimestral: | C8: 45688 | J8: IVA Mensal
C11: 1 | D11: 2 | E11: 3 | F11: 4 | G11: 5 | H11: 6 | I11: 7 | J11: 8 | K11: 9 | L11: 10 | M11: 11 | N11: 12
B12: 1ª Data - SAFT | C12: 45662 | D12: 45693 | E12: 45721 | F12: 45752 | G12: 45782 | H12: 45813 | I12: 45843 | J12: 45874 | K12: 45905 | L12: 45935 | M12: 45966 | N12: 45996
B13: 2ª Data - Segurança Social | C13: 45677 | D13: 45708 | E13: 45736 | F13: 45767 | G13: 45797 | H13: 45828 | I13: 45858 | J13: 45889 | K13: 45920 | L13: 45950 | M13: 45981 | N13: 46011
B14: 3ª Data | C14: 45858 | D14: 45950 | E14: 45677 | F14: 45767
C16: Serviços | D16: Produtos
B17: Rendimento Relevante | C17: 0.7 | D17: 0.2 | I17: SAFT | J17: SS | K17: DT
B18: Contribuição Mensal | C18: 0.214 | D18: 0.252 | H18: 1 | I18: 45662 | J18: 45677 | K18: 45688
H19: 2 | I19: 45693 | J19: 45708
B20: Valor Mínimo Contribuição | C20: 20 | H20: 3 | I20: 45721 | J20: 45736
H21: 4 | I21: 45752 | J21: 45767 | K21: 45777
B22: IVA | C22: Entrega | D22: Pagamento | H22: 5 | I22: 45782 | J22: 45797
B23: 1ºTrimestre | C23: 45797 | D23: 45802 | H23: 6 | I23: 45813 | J23: 45828
B24: 2ºTrimestre | C24: 45889 | D24: 45894 | H24: 7 | I24: 45843 | J24: 45858 | K24: 45869
B25: 3ºTrimestre | C25: 45981 | D25: 45986 | H25: 8 | I25: 45874 | J25: 45889
B26: 4ºTrimestre | C26: 45708 | D26: 45713 | H26: 9 | I26: 45905 | J26: 45920
H27: 10 | I27: 45935 | J27: 45950 | K27: 45961
B28: Valor limite despesas sem comprovativo | D28: 4462.15 | H28: 11 | I28: 45966 | J28: 45981
H29: 12 | I29: 45996 | J29: 46011
B30: Rendimento Coletável | D30: Taxa | E30: Parcela a abater
A31: 2024 | B31: Minimo | C31: Maximo
B32: - € | C32: 7703 | D32: 0.13 | E32: - €
B33: =+C32 -> 7703 | C33: 11623 | D33: 0.165 | E33: 269.61
B34: =+C33 -> 11623 | C34: 16472 | D34: 0.22 | E34: 908.92
B35: =+C34 -> 16472 | C35: 21321 | D35: 0.25 | E35: 1403.08
B36: =+C35 -> 21321 | C36: 27146 | D36: 0.32 | E36: 2898.61
B37: =+C36 -> 27146 | C37: 39791 | D37: 0.355 | E37: 3845.5
B38: =+C37 -> 39791 | C38: 43000 | D38: 0.435 | E38: 7029.08
B39: =+C38 -> 43000 | C39: 80000 | D39: 0.45 | E39: 7673.78
B40: =+C39 -> 80000 | C40: 3000000 | D40: 0.48 | E40: 10073.6
B43: Valor limite despesas sem comprovativo | D43: 4462.15
B44: Rendimento Coletável | D44: Taxa | E44: Parcela a abater
A45: 2025 | B45: Minimo | C45: Maximo
B46: - € | C46: 8059 | D46: 0.13 | E46: - €
B47: 8059 | C47: 12160 | D47: 0.165 | E47: 282.07
...

Sheet 1
A1: Análise Faturação e Despesas | Janeiro | TR1: JAN
C3: Resumo de Faturação e Gastos - Janeiro | L3: Fluxo de Caixa | T3: Valor a Separar de Impostos
C5: Total | E5: =SUM(E6:E10) -> 1586.5 | G5: Total | I5: =SUM(I6:I8) -> 548.2 | L5: Faturação | M5: =+L14 -> 1586.5 | N5: Recibo | O5: =+SUMIF(M16:M2599,"Pago",L16:L2499) -> 1586.5 | Q5: A receber | R5: =+SUMIF(M16:M2599,"Vencido",L16:L2499)+SUMIF(M16:M2599,"Pendente",L16:L2499) -> 0 | T5: IVA | U5: =+J14 -> 0
C6: =+Dados!F5 -> qEEG | E6: =+SUMIF(F16:F199994,C6,I16:I4994) -> 608 | G6: Despesas Variáveis | I6: =+SUMIF(T16:T199994,G6,U16:U4994) -> 0
C7: =+Dados!F6 -> NFB | E7: =+SUMIF(F16:F199994,C7,I16:I4994) -> 270.5 | G7: Despesas Fixas | I7: =+SUMIF(T16:T199994,G7,U16:U4994) -> 548.2 | L7: Despesas | M7: =+W14 -> 551.65 | N7: Pago | O7: =+SUMIF(X16:X2599,"Pago",W16:W2499) -> 551.65 | P7: A receber | Q7: A pagamento | R7: =+SUMIF(X16:X2599,"Vencido",W16:W2499)+SUMIF(X16:X2599,"Pendente",W16:W2499) -> 0 | T7: IRS | U7: =+'IRS-2025'!F23 -> 843.14973
C8: =+Dados!F7 -> Pack NFB | E8: =+SUMIF(F16:F199994,C8,I16:I4994) -> 708 | G8: Investimento | I8: =+SUMIF(T16:T199994,G8,U16:U4994) -> 0
C9: =+Dados!F11 -> 0 | E9: =+SUMIF(F16:F199994,C9,I16:I4994) -> 0
C10: =+Dados!F12 -> 0 | E10: =+SUMIF(F16:F199994,C10,I16:I4994) -> 0 | G10: Lucro | I10: =+E5-I5 -> 1038.3
B13: Faturação | P13: Despesas
E14: TOTAL | I14: =+SUM(Fat_Jan[Base]) -> 1586.5 | J14: =+SUM(Fat_Jan[[IVA ]]) -> 0 | K14: =+SUM(Fat_Jan[Retenção]) -> 0 | L14: =+SUM(Fat_Jan[Total]) -> 1586.5 | R14: TOTAL | U14: =+SUM(Desp_Jan[Base]) -> 548.2 | V14: =SUM(Desp_Jan[[IVA ]]) -> 3.45 | W14: =SUM(Desp_Jan[Total]) -> 551.65
B15: Data | C15: Cliente | D15: NIF | E15: Tipologia | F15: Descrição | G15: Nº Fatura | H15: Prestação | I15: Base | J15: IVA | K15: Retenção | L15: Total | M15: Estado | N15: Método Recebimento | P15: Data | Q15: Fornecedor | R15: NIF | S15: Nº Fatura | T15: Tipo | U15: Base | V15: IVA | W15: Total | X15: Estado | Y15: Método Pagamento
B16: 45660 | C16: João Vieira | D16: 0 | E16: Serviços | F16: qEEG | H16: 1 | I16: 65 | J16: 0 | K16: 0 | L16: =+I16+J16-K16 -> 65 | M16: Pago | N16: Numerário | P16: 45659 | Q16: Renda | R16: 0 | T16: Despesas Fixas | U16: 280 | V16: 0 | W16: 280 | X16: Pago | Y16: Transferência Bancária
B17: 45660 | C17: Inês Matos | D17: 0 | E17: Serviços | F17: qEEG | H17: 1 | I17: 65 | J17: 0 | K17: 0 | L17: =+I17+J17-K17 -> 65 | M17: Pago | N17: Numerário | P17: 45664 | Q17: TPA | R17: 0 | T17: Despesas Fixas | U17: 15 | V17: =+Desp_Jan[[#This Row],[Base]]*0.23 -> 3.45 | W17: =+Desp_Jan[[#This Row],[Base]]+Desp_Jan[[#This Row],[IVA ]] -> 18.45 | X17: Pago | Y17: Débito direto
B18: 45661 | C18: Ana Oliveira | D18: 0 | E18: Serviços | F18: qEEG | H18: 1 | I18: 65 | J18: 0 | K18: 0 | L18: =+I18+J18-K18 -> 65 | M18: Pago | N18: Numerário | P18: 45673 | Q18: SS | R18: 0 | T18: Despesas Fixas | U18: 20 | V18: 0 | W18: 20 | X18: Pago | Y18: Transferência Bancária
B19: 45661 | C19: Rui Fernandes | D19: 0 | E19: Serviços | F19: qEEG | H19: 1 | I19: 65 | J19: 0 | K19: 0 | L19: =+I19+J19-K19 -> 65 | M19: Pago | N19: Numerário | P19: 45667 | Q19: Eulália | R19: 0 | T19: Despesas Fixas | U19: 100 | V19: 0 | W19: 100 | X19: Pago | Y19: Transferência Bancária
B20: 45663 | C20: Fátima | D20: 0 | E20: Serviços | F20: qEEG | H20: 1 | I20: 65 | J20: 0 | K20: 0 | L20: =+I20+J20-K20 -> 65 | M20: Pago | N20: Numerário | P20: 45688 | Q20: Meta | R20: 217663923 | T20: Despesas Fixas | U20: 133.2 | V20: 0 | W20: 133.2 | X20: Pago | Y20: Débito direto
B21: 45663 | C21: Martim Silva | D21: 284976830 | E21: Serviços | F21: qEEG | G21: 1 | H21: 1 | I21: 65 | J21: 0 | K21: 0 | L21: =+I21+J21-K21 -> 65 | M21: Pago | N21: MBWay | V21: =+Desp_Jan[[#This Row],[Base]]*0.23 -> 0 | W21: =+Desp_Jan[[#This Row],[Base]]+Desp_Jan[[#This Row],[IVA ]] -> 0
B22: 45670 | C22: Inês Matos | D22: 0 | E22: Serviços | F22: NFB | H22: 1 | I22: 38.5 | J22: 0 | K22: 0 | L22: =+I22+J22-K22 -> 38.5 | M22: Pago | N22: Numerário | V22: =+Desp_Jan[[#This Row],[Base]]*0.23 -> 0 | W22: =+Desp_Jan[[#This Row],[Base]]+Desp_Jan[[#This Row],[IVA ]] -> 0
B23: 45670 | C23: João Afonso | D23: 285231022 | E23: Serviços | F23: NFB | G23: 3 | H23: 1 | I23: 55 | J23: 0 | K23: 0 | L23: =+I23+J23-K23 -> 55 | M23: Pago | N23: Numerário
B24: 45672 | C24: Martim Silva | D24: 284976830 | E24: Serviços | F24: qEEG | G24: 2 | H24: 1 | I24: 76.5 | J24: 0 | K24: 0 | L24: =+I24+J24-K24 -> 76.5 | M24: Pago | N24: MBWay
B25: 45672 | C25: José Ferreira | D25: 0 | E25: Serviços | F25: qEEG | H25: 1 | I25: 65 | J25: 0 | K25: 0 | L25: =+I25+J25-K25 -> 65 | M25: Pago | N25: Numerário
B26: 45673 | C26: Inês Matos | D26: 241710189 | E26: Serviços | F26: NFB | G26: 5 | H26: 1 | I26: 38.5 | J26: 0 | K26: 0 | L26: =+I26+J26-K26 -> 38.5 | M26: Pago | N26: Numerário
B27: 45674 | C27: Teresa Xavier | D27: 0 | E27: Serviços | F27: NFB | H27: 2 | I27: 100 | J27: 0 | K27: 0 | L27: =+I27+J27-K27 -> 100 | M27: Pago | N27: Numerário
B28: 45675 | C28: Gabriel Cruz | D28: 298308282 | E28: Serviços | F28: qEEG | G28: 4 | H28: 1 | I28: 76.5 | J28: 0 | K28: 0 | L28: =+I28+J28-K28 -> 76.5 | M28: Pago | N28: Numerário
B29: 45679 | C29: Fátima | D29: 0 | E29: Serviços | F29: Pack NFB | H29: 1 | I29: 308 | J29: 0 | K29: 0 | L29: =+I29+J29-K29 -> 308 | M29: Pago | N29: Numerário
B30: 45681 | C30: João Afonso | D30: 285231022 | E30: Serviços | F30: Pack NFB | G30: 6 | H30: 1 | I30: 400 | J30: 0 | K30: 0 | L30: =+I30+J30-K30 -> 400 | M30: Pago | N30: Numerário
B31: 45684 | C31: Inês Matos | D31: 0 | E31: Serviços | F31: NFB | H31: 1 | I31: 38.5 | J31: 0 | K31: 0 | L31: =+I31+J31-K31 -> 38.5 | M31: Pago | N31: Numerário

Sheet 2
A1: Análise Faturação e Despesas | Fevereiro | TR1: FEV
C3: Resumo de Faturação e Gastos - Fevereiro | L3: Fluxo de Caixa | T3: Valor a Separar de Impostos
C5: Total | E5: =SUM(E6:E10) -> 1084 | G5: Total | I5: =SUM(I6:I8) -> 545.94 | L5: Faturação | M5: =+L14 -> 1084 | N5: Recibo | O5: =+SUMIF(M16:M2599,"Pago",L16:L2499) -> 1084 | Q5: A receber | R5: =+SUMIF(M16:M2599,"Vencido",L16:L2499)+SUMIF(M16:M2599,"Pendente",L16:L2499) -> 0 | T5: IVA | U5: =+J14 -> 0
C6: =+Dados!F5 -> qEEG | E6: =+SUMIF(F16:F199994,C6,I16:I4994) -> 614.5 | G6: Despesas Variáveis | I6: =+SUMIF(T16:T199994,G6,U16:U4994) -> 0
C7: =+Dados!F6 -> NFB | E7: =+SUMIF(F16:F199994,C7,I16:I4994) -> 269.5 | G7: Despesas Fixas | I7: =+SUMIF(T16:T199994,G7,U16:U4994) -> 545.94 | L7: Despesas | M7: =+W14 -> 269.39 | N7: Pago | O7: =+SUMIF(X16:X2599,"Pago",W16:W2499) -> 269.39 | P7: A receber | Q7: A pagamento | R7: =+SUMIF(X16:X2599,"Vencido",W16:W2499)+SUMIF(X16:X2599,"Pendente",W16:W2499) -> 0 | T7: IRS | U7: =+'IRS-2025'!F23 -> 843.14973
C8: =+Dados!F7 -> Pack NFB | E8: =+SUMIF(F16:F199994,C8,I16:I4994) -> 200 | G8: Investimento | I8: =+SUMIF(T16:T199994,G8,U16:U4994) -> 0
C9: =+Dados!F11 -> 0 | E9: =+SUMIF(F16:F199994,C9,I16:I4994) -> 0
C10: =+Dados!F12 -> 0 | E10: =+SUMIF(F16:F199994,C10,I16:I4994) -> 0 | G10: Lucro | I10: =+E5-I5 -> 538.06
B13: Faturação | P13: Despesas
E14: TOTAL | I14: =+SUM(Fat_Fev[Base]) -> 1084 | J14: =+SUM(Fat_Fev[[IVA ]]) -> 0 | K14: =+SUM(Fat_Fev[Retenção]) -> 0 | L14: =+SUM(Fat_Fev[Total]) -> 1084 | R14: TOTAL | U14: =+SUM(Desp_Fev[Base]) -> 545.94 | V14: =SUM(Desp_Fev[[IVA ]]) -> 3.45 | W14: =SUM(Desp_Fev[Total]) -> 269.39
B15: Data | C15: Cliente | D15: NIF | E15: Tipologia | F15: Descrição | G15: Nº Fatura | H15: Prestação | I15: Base | J15: IVA | K15: Retenção | L15: Total | M15: Estado | N15: Método Recebimento | P15: Data | Q15: Fornecedor | R15: NIF | S15: Nº Fatura | T15: Tipo | U15: Base | V15: IVA | W15: Total | X15: Estado | Y15: Método Pagamento
B16: 45689 | C16: Beatriz Cerqueira | D16: 297521012 | E16: Serviços | F16: qEEG | G16: 7 | H16: 1 | I16: 76.5 | J16: 0 | K16: 0 | L16: =+I16+J16-K16 -> 76.5 | M16: Pago | N16: Multibanco | P16: 45691 | Q16: Renda | T16: Despesas Fixas | U16: 280 | V16: 0 | W16: 0 | X16: Pago | Y16: Transferência Bancária
B17: 45691 | C17: Inês Matos | D17: 241710189 | E17: Serviços | F17: NFB | G17: 8 | H17: 1 | I17: 38.5 | J17: 0 | K17: 0 | L17: =+I17+J17-K17 -> 38.5 | M17: Pago | N17: Numerário | P17: 45693 | Q17: TPA | T17: Despesas Fixas | U17: 15 | V17: =+Desp_Fev[[#This Row],[Base]]*0.23 -> 3.45 | W17: =+Desp_Fev[[#This Row],[Base]]+Desp_Fev[[#This Row],[IVA ]] -> 18.45 | X17: Pago | Y17: Débito direto
B18: 45695 | C18: Inês Matos | D18: 0 | E18: Serviços | F18: NFB | H18: 1 | I18: 38.5 | J18: 0 | K18: 0 | L18: =+I18+J18-K18 -> 38.5 | M18: Pago | N18: Numerário | P18: 45699 | Q18: Eulália | T18: Despesas Fixas | U18: 100 | V18: 0 | W18: 100 | X18: Pago | Y18: Transferência Bancária
B19: 45696 | C19: Lurdes | D19: 187354014 | E19: Serviços | F19: qEEG | G19: 9 | H19: 1 | I19: 85 | J19: 0 | K19: 0 | L19: =+I19+J19-K19 -> 85 | M19: Pago | N19: Multibanco | P19: 45705 | Q19: SS | T19: Despesas Fixas | U19: 20 | V19: 0 | W19: 20 | X19: Pago | Y19: Transferência Bancária
B20: 45696 | C20: Rugal | D20: 0 | E20: Serviços | F20: qEEG | H20: 1 | I20: 65 | J20: 0 | K20: 0 | L20: =+I20+J20-K20 -> 65 | M20: Pago | N20: Numerário | P20: 45707 | Q20: Conceição | T20: Despesas Fixas | U20: 31.5 | V20: 0 | W20: 31.5 | X20: Pago | Y20: Transferência Bancária
B21: 45694 | C21: Ângela | D21: 0 | E21: Serviços | F21: qEEG | H21: 1 | I21: 65 | J21: 0 | K21: 0 | L21: =+I21+J21-K21 -> 65 | M21: Pago | N21: Numerário | P21: 45713 | Q21: ChatGPT | T21: Despesas Fixas | U21: 19.15 | V21: 0 | W21: 19.15 | X21: Pago | Y21: Transferência Bancária
B22: 45698 | C22: Lourenço Cunha | D22: 288608143 | E22: Serviços | F22: qEEG | G22: 10 | H22: 1 | I22: 76.5 | J22: 0 | K22: 0 | L22: =+I22+J22-K22 -> 76.5 | M22: Pago | N22: Multibanco | P22: 45713 | Q22: META | T22: Despesas Fixas | U22: 79.69 | V22: 0 | W22: 79.69 | X22: Pago | Y22: Débito direto
B23: 45698 | C23: Afonso Coelho | D23: 319466493 | E23: Serviços | F23: qEEG | G23: 12 | H23: 1 | I23: 85 | J23: 0 | K23: 0 | L23: =+I23+J23-K23 -> 85 | M23: Pago | N23: Transferência Bancária | P23: 45713 | Q23: Banco/Imp/selo | T23: Despesas Fixas | U23: 0.6 | V23: 0 | W23: 0.6 | X23: Pago | Y23: Débito direto
B24: 45698 | C24: Afonso Coelho | D24: 319466493 | E24: Serviços | F24: Pack NFB | G24: 12 | H24: 1 | I24: 200 | J24: 0 | K24: 0 | L24: =+I24+J24-K24 -> 200 | M24: Pago | N24: Transferência Bancária
B25: 45700 | C25: Dinis Pereira | D25: 273251163 | E25: Serviços | F25: qEEG | G25: 11 | H25: 1 | I25: 85 | J25: 0 | K25: 0 | L25: =+I25+J25-K25 -> 85 | M25: Pago | N25: Multibanco
B26: 45701 | C26: Inês Matos | D26: 241710189 | E26: Serviços | F26: NFB | G26: 13 | H26: 1 | I26: 38.5 | J26: 0 | K26: 0 | L26: 38.5 | M26: Pago | N26: Numerário
B27: 45706 | C27: Inês Matos | D27: 0 | E27: Serviços | F27: NFB | H27: 1 | I27: 38.5 | J27: 0 | K27: 0 | L27: =+I27+J27-K27 -> 38.5 | M27: Pago | N27: Numerário
B28: 45708 | C28: Inês Matos | D28: 241710189 | E28: Serviços | F28: NFB | G28: 14 | H28: 1 | I28: 38.5 | J28: 0 | K28: 0 | L28: =+I28+J28-K28 -> 38.5 | M28: Pago | N28: Numerário
B29: 45708 | C29: João Miguel | D29: 297118668 | E29: Serviços | F29: qEEG | G29: 15 | H29: 1 | I29: 76.5 | J29: 0 | K29: 0 | L29: =+I29+J29-K29 -> 76.5 | M29: Pago | N29: Numerário
B30: 45715 | C30: Inês Matos | D30: 0 | E30: Serviços | F30: NFB | H30: 1 | I30: 38.5 | J30: 0 | K30: 0 | L30: =+I30+J30-K30 -> 38.5 | M30: Pago | N30: Numerário
B31: 45713 | C31: Inês Matos | D31: 0 | E31: Serviços | F31: NFB | H31: 1 | I31: 38.5 | J31: 0 | K31: 0 | L31: =+I31+J31-K31 -> 38.5 | M31: Pago | N31: Numerário

Sheet 3
A1: Análise Faturação e Despesas | Março | TR1: MAR
C3: Resumo de Faturação e Gastos - Março | L3: Fluxo de Caixa | T3: Valor a Separar de Impostos
C5: Total | E5: =SUM(E6:E10) -> 1360.5 | G5: Total | I5: =SUM(I6:I8) -> 578.75 | L5: Faturação | M5: =+L14 -> 1360.5 | N5: Recibo | O5: =+SUMIF(M16:M2599,"Pago",L16:L2499) -> 1360.5 | Q5: A receber | R5: =+SUMIF(M16:M2599,"Vencido",L16:L2499)+SUMIF(M16:M2599,"Pendente",L16:L2499) -> 0 | T5: IVA | U5: =+J14 -> 0
C6: =+Dados!F5 -> qEEG | E6: =+SUMIF(F16:F199994,C6,I16:I4994) -> 460 | G6: Despesas Variáveis | I6: =+SUMIF(T16:T199994,G6,U16:U4994) -> 0
C7: =+Dados!F6 -> NFB | E7: =+SUMIF(F16:F199994,C7,I16:I4994) -> 192.5 | G7: Despesas Fixas | I7: =+SUMIF(T16:T199994,G7,U16:U4994) -> 578.75 | L7: Despesas | M7: =+W14 -> 582.78 | N7: Pago | O7: =+SUMIF(X16:X2599,"Pago",W16:W2499) -> 582.78 | P7: A receber | Q7: A pagamento | R7: =+SUMIF(X16:X2599,"Vencido",W16:W2499)+SUMIF(X16:X2599,"Pendente",W16:W2499) -> 0 | T7: IRS | U7: =+'IRS-2025'!F23 -> 843.14973
C8: =+Dados!F7 -> Pack NFB | E8: =+SUMIF(F16:F199994,C8,I16:I4994) -> 708 | G8: Investimento | I8: =+SUMIF(T16:T199994,G8,U16:U4994) -> 0
C9: =+Dados!F11 -> 0 | E9: =+SUMIF(F16:F199994,C9,I16:I4994) -> 0
C10: =+Dados!F12 -> 0 | E10: =+SUMIF(F16:F199994,C10,I16:I4994) -> 0 | G10: Lucro | I10: =+E5-I5 -> 781.75
B13: Faturação | P13: Despesas
E14: TOTAL | I14: =+SUM(Fat_Mar[Base]) -> 1360.5 | J14: =+SUM(Fat_Mar[[IVA ]]) -> 0 | K14: =+SUM(Fat_Mar[Retenção]) -> 0 | L14: =+SUM(Fat_Mar[Total]) -> 1360.5 | R14: TOTAL | U14: =+SUM(Desp_Mar[Base]) -> 579.33 | V14: =SUM(Desp_Mar[[IVA ]]) -> 3.45 | W14: =SUM(Desp_Mar[Total]) -> 582.78
B15: Data | C15: Cliente | D15: NIF | E15: Tipologia | F15: Descrição | G15: Nº Fatura | H15: Prestação | I15: Base | J15: IVA | K15: Retenção | L15: Total | M15: Estado | N15: Método Recebimento | P15: Data | Q15: Fornecedor | R15: NIF | S15: Nº Fatura | T15: Tipo | U15: Base | V15: IVA | W15: Total | X15: Estado | Y15: Método Pagamento
B16: 45726 | C16: Inês Matos | D16: 0 | E16: Serviços | F16: NFB | H16: 1 | I16: 38.5 | J16: 0 | K16: 0 | L16: =+I16+J16-K16 -> 38.5 | M16: Pago | N16: Numerário | P16: 45718 | Q16: Renda | T16: Despesas Fixas | U16: 280 | V16: 0 | W16: 280 | X16: Pago | Y16: Transferência Bancária
B17: 45729 | C17: Vitória | D17: 280321244 | E17: Serviços | F17: qEEG | G17: 16 | H17: 1 | I17: 85 | J17: 0 | K17: 0 | L17: =+I17+J17-K17 -> 85 | M17: Pago | N17: Multibanco | P17: 45747 | Q17: Eulalia | T17: Despesas Fixas | U17: 100 | V17: 0 | W17: =+Desp_Mar[[#This Row],[Base]]+Desp_Mar[[#This Row],[IVA ]] -> 100 | X17: Pago | Y17: Transferência Bancária
B18: 45733 | C18: Inês Matos | D18: 0 | E18: Serviços | F18: NFB | H18: 1 | I18: 38.5 | J18: 0 | K18: 0 | L18: =+I18+J18-K18 -> 38.5 | M18: Pago | N18: Numerário | P18: 45722 | Q18: TPA | T18: Despesas Fixas | U18: 15 | V18: =+Desp_Mar[[#This Row],[Base]]*0.23 -> 3.45 | W18: =+Desp_Mar[[#This Row],[Base]]+Desp_Mar[[#This Row],[IVA ]] -> 18.45 | X18: Pago | Y18: Débito direto
B19: 45730 | C19: Joel | D19: 0 | E19: Serviços | F19: qEEG | H19: 1 | I19: 65 | J19: 0 | K19: 0 | L19: =+I19+J19-K19 -> 65 | M19: Pago | N19: Numerário | P19: 45747 | Q19: META | T19: Despesas Fixas | U19: 97.87 | V19: 0 | W19: =+Desp_Mar[[#This Row],[Base]]+Desp_Mar[[#This Row],[IVA ]] -> 97.87 | X19: Pago | Y19: Débito direto
B20: 45731 | C20: Catarina AuraClinc | D20: 0 | E20: Serviços | F20: qEEG | H20: 1 | I20: 75 | J20: 0 | K20: 0 | L20: =+I20+J20-K20 -> 75 | M20: Pago | N20: Numerário | P20: 45727 | Q20: SS | T20: Despesas Fixas | U20: 20 | V20: 0 | W20: =+Desp_Mar[[#This Row],[Base]]+Desp_Mar[[#This Row],[IVA ]] -> 20 | X20: Pago | Y20: Transferência Bancária
B21: 45738 | C21: João Paulo | D21: 192490834 | E21: Serviços | F21: qEEG | G21: 19 | H21: 1 | I21: 85 | J21: 0 | K21: 0 | L21: =+I21+J21-K21 -> 85 | M21: Pago | N21: Multibanco | P21: 45737 | Q21: Conceição | T21: Despesas Fixas | U21: 47.35 | V21: 0 | W21: =+Desp_Mar[[#This Row],[Base]]+Desp_Mar[[#This Row],[IVA ]] -> 47.35 | X21: Pago | Y21: Transferência Bancária
B22: 45744 | C22: João Afonso | D22: 285231022 | E22: Serviços | F22: Pack NFB | G22: 17/30 | H22: 1 | I22: 400 | J22: 0 | K22: 0 | L22: =+I22+J22-K22 -> 400 | M22: Pago | N22: Numerário | P22: 45741 | Q22: ChatGPT | T22: Despesas Fixas | U22: 18.53 | V22: 0 | W22: =+Desp_Mar[[#This Row],[Base]]+Desp_Mar[[#This Row],[IVA ]] -> 18.53 | X22: Pago | Y22: Débito direto
B23: 45737 | C23: Luis Pedro | D23: 0 | E23: Serviços | F23: qEEG | H23: 1 | I23: 65 | J23: 0 | K23: 0 | L23: =+I23+J23-K23 -> 65 | M23: Pago | N23: Numerário | P23: 45741 | Q23: Banco/Selp/Imp | U23: 0.58 | V23: 0 | W23: =+Desp_Mar[[#This Row],[Base]]+Desp_Mar[[#This Row],[IVA ]] -> 0.58 | X23: Pago | Y23: Débito direto
B24: 45741 | C24: Joel | D24: 0 | E24: Serviços | F24: Pack NFB | H24: 1 | I24: 308 | J24: 0 | K24: 0 | L24: =+I24+J24-K24 -> 308 | M24: Pago | N24: Numerário
B25: 45736 | C25: Inês Matos | D25: 0 | E25: Serviços | F25: NFB | H25: 1 | I25: 38.5 | J25: 0 | K25: 0 | L25: =+I25+J25-K25 -> 38.5 | M25: Pago | N25: Numerário
B26: 45742 | C26: Inês Matos | D26: 0 | E26: Serviços | F26: NFB | H26: 1 | I26: 38.5 | J26: 0 | K26: 0 | L26: =+I26+J26-K26 -> 38.5 | M26: Pago | N26: Numerário
B27: 45747 | C27: Inês Matos | D27: 0 | E27: Serviços | F27: NFB | H27: 1 | I27: 38.5 | J27: 0 | K27: 0 | L27: =+I27+J27-K27 -> 38.5 | M27: Pago | N27: Numerário
B28: 45744 | C28: Gabriel Cardoso | D28: 308014448 | E28: Serviços | F28: qEEG | G28: 18 | H28: 1 | I28: 85 | J28: 0 | K28: 0 | L28: =+I28+J28-K28 -> 85 | M28: Pago | N28: Multibanco

Sheet 4
A1: Análise Faturação e Despesas | Abril | TR1: ABR
TR2: {=IF(ISERROR(MATCH(_xlfn.ANCHORARRAY('3'!#REF!),TabelaDesp[Despesas],0)),"Faturação","Despesas")} -> Faturação | TS2: Curso | TT2: {=IF(_xlfn.ANCHORARRAY('3'!#REF!)="Faturação",SUMIFS(Fat_Abr[Base],Fat_Abr[Descrição],_xlfn.ANCHORARRAY('3'!#REF!)),SUMIFS(Desp_Abr[Base],Desp_Abr[Tipo],_xlfn.ANCHORARRAY('3'!#REF!)))} -> #REF! | TV2: {=OFFSET($TR$2,0,0,COUNTA(_xlfn.ANCHORARRAY($TR$2)),2)} -> Faturação | TW2: Curso | TX2: {=OFFSET($TT$2,0,0,COUNTA(_xlfn.ANCHORARRAY($TT$2)),1)} -> #REF!
C3: Resumo de Faturação e Gastos - Abril | L3: Fluxo de Caixa | T3: Valor a Separar de Impostos
C5: Total | E5: =SUM(E6:E10) -> 2014 | G5: Total | I5: =SUM(I6:I8) -> 3637.35 | L5: Faturação | M5: =+L14 -> 2014 | N5: Recibo | O5: =+SUMIF(M16:M2599,"Pago",L16:L2499) -> 2014 | Q5: A receber | R5: =+SUMIF(M16:M2599,"Vencido",L16:L2499)+SUMIF(M16:M2599,"Pendente",L16:L2499) -> 0 | T5: IVA | U5: =+J14 -> 0
C6: =+Dados!F5 -> qEEG | E6: =+SUMIF(F16:F199994,C6,I16:I4994) -> 565 | G6: Despesas Variáveis | I6: =+SUMIF(T16:T199994,G6,U16:U4994) -> 3113.59
C7: =+Dados!F6 -> NFB | E7: =+SUMIF(F16:F199994,C7,I16:I4994) -> 341 | G7: Despesas Fixas | I7: =+SUMIF(T16:T199994,G7,U16:U4994) -> 523.76 | L7: Despesas | M7: =+W14 -> 3640.8 | N7: Pago | O7: =+SUMIF(X16:X2599,"Pago",W16:W2499) -> 3640.8 | P7: A receber | Q7: A pagamento | R7: =+SUMIF(X16:X2599,"Vencido",W16:W2499)+SUMIF(X16:X2599,"Pendente",W16:W2499) -> 0 | T7: IRS | U7: =+'IRS-2025'!F23 -> 843.14973
C8: =+Dados!F7 -> Pack NFB | E8: =+SUMIF(F16:F199994,C8,I16:I4994) -> 1108 | G8: Investimento | I8: =+SUMIF(T16:T199994,G8,U16:U4994) -> 0
C9: =+Dados!F11 -> 0 | E9: =+SUMIF(F16:F199994,C9,I16:I4994) -> 0
C10: =+Dados!F12 -> 0 | E10: =+SUMIF(F16:F199994,C10,I16:I4994) -> 0 | G10: Lucro | I10: =+E5-I5 -> -1623.35
B13: Faturação | P13: Despesas
E14: TOTAL | I14: =+SUM(Fat_Abr[Base]) -> 2014 | J14: =+SUM(Fat_Abr[[IVA ]]) -> 0 | K14: =+SUM(Fat_Abr[Retenção]) -> 0 | L14: =+SUM(Fat_Abr[Total]) -> 2014 | R14: TOTAL | U14: =+SUM(Desp_Abr[Base]) -> 3637.35 | V14: =SUM(Desp_Abr[[IVA ]]) -> 3.45 | W14: =SUM(Desp_Abr[Total]) -> 3640.8
B15: Data | C15: Cliente | D15: NIF | E15: Tipologia | F15: Descrição | G15: Nº Fatura | H15: Prestação | I15: Base | J15: IVA | K15: Retenção | L15: Total | M15: Estado | N15: Método Recebimento | P15: Data | Q15: Fornecedor | R15: NIF | S15: Nº Fatura | T15: Tipo | U15: Base | V15: IVA | W15: Total | X15: Estado | Y15: Método Pagamento
B16: 45750 | C16: Inês Matos | D16: 0 | E16: Serviços | F16: NFB | H16: 1 | I16: 38.5 | J16: 0 | K16: 0 | L16: =+I16+J16-K16 -> 38.5 | M16: Pago | N16: Numerário | P16: 45750 | Q16: TPA | T16: Despesas Fixas | U16: 15 | V16: =+Desp_Abr[[#This Row],[Base]]*0.23 -> 3.45 | W16: =+Desp_Abr[[#This Row],[Base]]+Desp_Abr[[#This Row],[IVA ]] -> 18.45 | X16: Pago | Y16: Débito direto
B17: 45751 | C17: Inês Matos | D17: 0 | E17: Serviços | F17: NFB | H17: 1 | I17: 38.5 | J17: 0 | K17: 0 | L17: =+I17+J17-K17 -> 38.5 | M17: Pago | N17: Numerário | P17: 45754 | Q17: Renda | T17: Despesas Fixas | U17: 280 | V17: 0 | W17: 280 | X17: Pago | Y17: Transferência Bancária
B18: 45754 | C18: Inês Matos | D18: 0 | E18: Serviços | F18: NFB | H18: 1 | I18: 38.5 | J18: 0 | K18: 0 | L18: =+I18+J18-K18 -> 38.5 | M18: Pago | N18: Numerário | P18: 45754 | Q18: Neuroguide | T18: Despesas Variáveis | U18: 3113.59 | V18: 0 | W18: 3113.59 | X18: Pago | Y18: Transferência Bancária
B19: 45756 | C19: Gabriel Cardoso | D19: 308014448 | E19: Serviços | F19: NFB | G19: 20 | H19: 1 | I19: 55 | J19: 0 | K19: 0 | L19: =+I19+J19-K19 -> 55 | M19: Pago | N19: MBWay | P19: 45770 | Q19: Meta | T19: Despesas Fixas | U19: 143.89 | V19: 0 | W19: =+Desp_Abr[[#This Row],[Base]]+Desp_Abr[[#This Row],[IVA ]] -> 143.89 | X19: Pago | Y19: Débito direto
B20: 45757 | C20: Inês Matos | D20: 0 | E20: Serviços | F20: NFB | H20: 1 | I20: 38.5 | J20: 0 | K20: 0 | L20: =+I20+J20-K20 -> 38.5 | M20: Pago | N20: Numerário | P20: 45760 | Q20: SS | T20: Despesas Fixas | U20: 20 | V20: 0 | W20: =+Desp_Abr[[#This Row],[Base]]+Desp_Abr[[#This Row],[IVA ]] -> 20 | X20: Pago | Y20: Transferência Bancária
B21: 45758 | C21: Gabriel Cardoso | D21: 308014448 | E21: Serviços | F21: NFB | G21: 21 | H21: 1 | I21: 55 | J21: 0 | K21: 0 | L21: =+I21+J21-K21 -> 55 | M21: Pago | N21: MBWay | P21: 45775 | Q21: ChatGPT | T21: Despesas Fixas | U21: 17.52 | V21: 0 | W21: 17.52 | X21: Pago | Y21: Débito direto
B22: 45761 | C22: Inês Matos | D22: 0 | E22: Serviços | F22: NFB | H22: 1 | I22: 38.5 | J22: 0 | K22: 0 | L22: =+I22+J22-K22 -> 38.5 | M22: Pago | N22: Numerário | P22: 45775 | Q22: Conceição | T22: Despesas Fixas | U22: 46.8 | V22: 0 | W22: =+Desp_Abr[[#This Row],[Base]]+Desp_Abr[[#This Row],[IVA ]] -> 46.8 | X22: Pago | Y22: Transferência Bancária
B23: 45764 | C23: Inês Matos | D23: 0 | E23: Serviços | F23: NFB | H23: 1 | I23: 38.5 | J23: 0 | K23: 0 | L23: =+I23+J23-K23 -> 38.5 | M23: Pago | N23: Numerário | P23: 45775 | Q23: Banco/selo/im | T23: Despesas Fixas | U23: 0.55 | V23: 0 | W23: =+Desp_Abr[[#This Row],[Base]]+Desp_Abr[[#This Row],[IVA ]] -> 0.55 | X23: Pago | Y23: Débito direto
B24: 45765 | C24: António Barbosa | D24: 178479691 | E24: Serviços | F24: qEEG | G24: 22 | H24: 1 | I24: 75 | J24: 0 | K24: 0 | L24: =+I24+J24-K24 -> 75 | M24: Pago | N24: Numerário
B25: 45765 | C25: Pedro Fonseca | D25: 295081457 | E25: Serviços | F25: qEEG | G25: 23 | H25: 1 | I25: 85 | J25: 0 | K25: 0 | L25: =+I25+J25-K25 -> 85 | M25: Pago | N25: Multibanco
B26: 45769 | C26: Paulo Gomes | D26: 241473314 | E26: Serviços | F26: qEEG | G26: 24 | H26: 1 | I26: 85 | J26: 0 | K26: 0 | L26: =+I26+J26-K26 -> 85 | M26: Pago | N26: Numerário
B27: 45777 | C27: Alexandre | D27: 234558504 | E27: Serviços | F27: qEEG | G27: 28 | H27: 1 | I27: 85 | J27: 0 | K27: 0 | L27: =+I27+J27-K27 -> 85 | M27: Pago | N27: Multibanco
B28: 45777 | C28: Ismael | D28: 230682219 | E28: Serviços | F28: qEEG | G28: 29 | H28: 1 | I28: 85 | J28: 0 | K28: 0 | L28: 85 | M28: Pago | N28: Multibanco
B29: 45777 | C29: Eulalia | D29: 0 | E29: Serviços | F29: qEEG | H29: 1 | I29: 65 | J29: 0 | K29: 0 | L29: =+I29+J29-K29 -> 65 | M29: Pago | N29: Numerário
B30: 45773 | C30: Pedro Fonseca | D30: 295081457 | E30: Serviços | F30: Pack NFB | G30: 25 | H30: 1 | I30: 400 | J30: 0 | K30: 0 | L30: =+I30+J30-K30 -> 400 | M30: Pago | N30: Multibanco
B31: 45773 | C31: António Barbosa | D31: 178479691 | E31: Serviços | F31: Pack NFB | G31: 27 | H31: 1 | I31: 400 | J31: 0 | K31: 0 | L31: =+I31+J31-K31 -> 400 | M31: Pago | N31: Numerário
B32: 45773 | C32: Duarte teixeira | D32: 282896228 | E32: Serviços | F32: qEEG | G32: 26 | H32: 1 | I32: 85 | J32: 0 | K32: 0 | L32: =+I32+J32-K32 -> 85 | M32: Pago | N32: Numerário
B33: 45773 | C33: Joel | D33: 0 | E33: Serviços | F33: Pack NFB | H33: 1 | I33: 308 | J33: 0 | K33: 0 | L33: =+I33+J33-K33 -> 308 | M33: Pago | N33: Numerário

Sheet 5
A1: Análise Faturação e Despesas | Maio | TR1: MAI
TR2: Faturação | TS2: Curso | TT2: 0 | TV2: Faturação | TW2: Curso | TX2: 0
C3: Resumo de Faturação e Gastos - Maio | L3: Fluxo de Caixa | T3: Valor a Separar de Impostos
C5: Total | E5: =SUM(E6:E10) -> 2913 | G5: Total | I5: =SUM(I6:I8) -> 1391.024 | L5: Faturação | M5: =+L14 -> 2913 | N5: Recibo | O5: =+SUMIF(M16:M2599,"Pago",L16:L2499) -> 2913 | Q5: A receber | R5: =+SUMIF(M16:M2599,"Vencido",L16:L2499)+SUMIF(M16:M2599,"Pendente",L16:L2499) -> 0 | T5: IVA | U5: =+J14 -> 0
C6: =+Dados!F5 -> qEEG | E6: =+SUMIF(F16:F199994,C6,I16:I4994) -> 255 | G6: Despesas Variáveis | I6: =+SUMIF(T16:T199994,G6,U16:U4994) -> 69.444
C7: =+Dados!F6 -> NFB | E7: =+SUMIF(F16:F199994,C7,I16:I4994) -> 350 | G7: Despesas Fixas | I7: =+SUMIF(T16:T199994,G7,U16:U4994) -> 1321.58 | L7: Despesas | M7: =+W14 -> 1394.474 | N7: Pago | O7: =+SUMIF(X16:X2599,"Pago",W16:W2499) -> 1394.474 | P7: A receber | Q7: A pagamento | R7: =+SUMIF(X16:X2599,"Vencido",W16:W2499)+SUMIF(X16:X2599,"Pendente",W16:W2499) -> 0 | T7: IRS | U7: =+'IRS-2025'!F23 -> 843.14973
C8: =+Dados!F7 -> Pack NFB | E8: =+SUMIF(F16:F199994,C8,I16:I4994) -> 2308 | G8: Investimento | I8: =+SUMIF(T16:T199994,G8,U16:U4994) -> 0
C9: =+Dados!F11 -> 0 | E9: =+SUMIF(F16:F199994,C9,I16:I4994) -> 0
C10: =+Dados!F12 -> 0 | E10: =+SUMIF(F16:F199994,C10,I16:I4994) -> 0 | G10: Lucro | I10: =+E5-I5 -> 1521.976
B13: Faturação | P13: Despesas
E14: TOTAL | I14: =+SUM(Fat_Mai[Base]) -> 2913 | J14: =+SUM(Fat_Mai[[IVA ]]) -> 0 | K14: =+SUM(Fat_Mai[Retenção]) -> 0 | L14: =+SUM(Fat_Mai[Total]) -> 2913 | R14: TOTAL | U14: =+SUM(Desp_Mai[Base]) -> 1391.024 | V14: =SUM(Desp_Mai[[IVA ]]) -> 3.45 | W14: =SUM(Desp_Mai[Total]) -> 1394.474
B15: Data | C15: Cliente | D15: NIF | E15: Tipologia | F15: Descrição | G15: Nº Fatura | H15: Prestação | I15: Base | J15: IVA | K15: Retenção | L15: Total | M15: Estado | N15: Método Recebimento | P15: Data | Q15: Fornecedor | R15: NIF | S15: Nº Fatura | T15: Tipo | U15: Base | V15: IVA | W15: Total | X15: Estado | Y15: Método Pagamento
B16: 45779 | C16: Micael Silva | D16: 219466106 | E16: Serviços | F16: qEEG | G16: 31 | H16: 1 | I16: 85 | J16: 0 | K16: 0 | L16: =+I16+J16-K16 -> 85 | M16: Pago | N16: Numerário | P16: 45783 | Q16: Eulalia | T16: Despesas Fixas | U16: 200 | V16: 0 | W16: =+Desp_Mai[[#This Row],[Base]]+Desp_Mai[[#This Row],[IVA ]] -> 200 | X16: Pago | Y16: Transferência Bancária
B17: 45783 | C17: Alexandre | D17: 234558504 | E17: Serviços | F17: Pack NFB | G17: 32 | H17: 1 | I17: 400 | J17: 0 | K17: 0 | L17: =+I17+J17-K17 -> 400 | M17: Pago | N17: Multibanco | P17: 45782 | Q17: Renda | T17: Despesas Fixas | U17: 280 | V17: 0 | W17: =+Desp_Mai[[#This Row],[Base]]+Desp_Mai[[#This Row],[IVA ]] -> 280 | X17: Pago | Y17: Transferência Bancária
B18: 45785 | C18: Micael Silva | D18: 219466106 | E18: Serviços | F18: Pack NFB | G18: 33 | H18: 1 | I18: 400 | J18: 0 | K18: 0 | L18: =+I18+J18-K18 -> 400 | M18: Pago | N18: Multibanco | P18: 45783 | Q18: TPA | T18: Despesas Fixas | U18: 15 | V18: =+Desp_Mai[[#This Row],[Base]]*0.23 -> 3.45 | W18: =+Desp_Mai[[#This Row],[Base]]+Desp_Mai[[#This Row],[IVA ]] -> 18.45 | X18: Pago | Y18: Débito direto
B19: 45785 | C19: Ismael | D19: 230682219 | E19: Serviços | F19: NFB | G19: 34 | H19: 1 | I19: 50 | J19: 0 | K19: 0 | L19: =+I19+J19-K19 -> 50 | M19: Pago | N19: Multibanco | P19: 45786 | Q19: Man Conta | T19: Despesas Fixas | U19: 4.99 | V19: 0 | W19: 4.99 | X19: Pago | Y19: Débito direto
B20: 45790 | C20: Ismael | D20: 230682219 | E20: Serviços | F20: NFB | G20: 35 | H20: 1 | I20: 50 | J20: 0 | K20: 0 | L20: =+I20+J20-K20 -> 50 | M20: Pago | N20: Multibanco | P20: 45786 | Q20: imp selo | T20: Despesas Fixas | U20: 0.2 | V20: 0 | W20: =+Desp_Mai[[#This Row],[Base]]+Desp_Mai[[#This Row],[IVA ]] -> 0.2 | X20: Pago | Y20: Débito direto
B21: 45792 | C21: Ismael | D21: 230682219 | E21: Serviços | F21: NFB | G21: 36 | H21: 1 | I21: 50 | J21: 0 | K21: 0 | L21: =+I21+J21-K21 -> 50 | M21: Pago | N21: Multibanco | P21: 45784 | Q21: Amazon | T21: Despesas Variáveis | U21: 62.444 | V21: 0 | W21: =+Desp_Mai[[#This Row],[Base]]+Desp_Mai[[#This Row],[IVA ]] -> 62.444 | X21: Pago | Y21: Transferência Bancária
B22: 45793 | C22: Miguel Anjo | D22: 241865352 | E22: Serviços | F22: qEEG | G22: 37 | H22: 1 | I22: 85 | J22: 0 | K22: 0 | L22: =+I22+J22-K22 -> 85 | M22: Pago | N22: Multibanco | P22: 45791 | Q22: TeclaJo | T22: Despesas Variáveis | U22: 7 | V22: 0 | W22: =+Desp_Mai[[#This Row],[Base]]+Desp_Mai[[#This Row],[IVA ]] -> 7 | X22: Pago | Y22: Multibanco
B23: 45794 | C23: Pedro Fonseca | D23: 295081457 | E23: Serviços | F23: Pack NFB | G23: 38 | H23: 1 | I23: 400 | J23: 0 | K23: 0 | L23: =+I23+J23-K23 -> 400 | M23: Pago | N23: Multibanco | P23: 45800 | Q23: Meta | T23: Despesas Fixas | U23: 178.32 | V23: 0 | W23: =+Desp_Mai[[#This Row],[Base]]+Desp_Mai[[#This Row],[IVA ]] -> 178.32 | X23: Pago | Y23: Débito direto
B24: 45797 | C24: Ismael | D24: 230682219 | E24: Serviços | F24: NFB | G24: 39 | H24: 1 | I24: 50 | J24: 0 | K24: 0 | L24: =+I24+J24-K24 -> 50 | M24: Pago | N24: Multibanco | P24: 45807 | Q24: Marketing | T24: Despesas Fixas | U24: 560 | V24: 0 | W24: =+Desp_Mai[[#This Row],[Base]]+Desp_Mai[[#This Row],[IVA ]] -> 560 | X24: Pago | Y24: Transferência Bancária
B25: 45799 | C25: Guilherme (Aida) | D25: 239487168 | E25: Serviços | F25: qEEG | G25: 40 | H25: 1 | I25: 85 | J25: 0 | K25: 0 | L25: =+I25+J25-K25 -> 85 | M25: Pago | N25: MBWay | P25: 45799 | Q25: Conceição | T25: Despesas Fixas | U25: 44.74 | V25: 0 | W25: =+Desp_Mai[[#This Row],[Base]]+Desp_Mai[[#This Row],[IVA ]] -> 44.74 | X25: Pago | Y25: Transferência Bancária
B26: 45800 | C26: Ismael | D26: 230682219 | E26: Serviços | F26: NFB | G26: 41 | H26: 1 | I26: 50 | J26: 0 | K26: 0 | L26: =+I26+J26-K26 -> 50 | M26: Pago | N26: Multibanco | P26: 45803 | Q26: ChatGPT | T26: Despesas Fixas | U26: 17.77 | V26: 0 | W26: =+Desp_Mai[[#This Row],[Base]]+Desp_Mai[[#This Row],[IVA ]] -> 17.77 | X26: Pago | Y26: Débito direto
B27: 45801 | C27: António Pereira | D27: 178479691 | E27: Serviços | F27: Pack NFB | G27: 42 | H27: 1 | I27: 400 | J27: 0 | K27: 0 | L27: =+I27+J27-K27 -> 400 | M27: Pago | N27: Numerário | P27: 45803 | Q27: banco | T27: Despesas Fixas | U27: 0.56 | V27: 0 | W27: =+Desp_Mai[[#This Row],[Base]]+Desp_Mai[[#This Row],[IVA ]] -> 0.56 | X27: Pago | Y27: Débito direto
B28: 45804 | C28: Ismael | D28: 230682219 | E28: Serviços | F28: NFB | G28: 43 | H28: 1 | I28: 50 | J28: 0 | K28: 0 | L28: =+I28+J28-K28 -> 50 | M28: Pago | N28: Multibanco | P28: 45797 | Q28: SS | T28: Despesas Fixas | U28: 20 | V28: 0 | W28: =+Desp_Mai[[#This Row],[Base]]+Desp_Mai[[#This Row],[IVA ]] -> 20 | X28: Pago | Y28: Transferência Bancária
B29: 45784 | C29: Joel | D29: 0 | E29: Serviços | F29: Pack NFB | H29: 1 | I29: 308 | J29: 0 | K29: 0 | L29: =+I29+J29-K29 -> 308 | M29: Pago | N29: Numerário
B30: 45806 | C30: Ismael | D30: 230682219 | E30: Serviços | F30: NFB | G30: 44 | H30: 1 | I30: 50 | J30: 0 | K30: 0 | L30: =+I30+J30-K30 -> 50 | M30: Pago | N30: Multibanco
B31: 45806 | C31: Micael Silva | D31: 219466106 | E31: Serviços | F31: Pack NFB | G31: 45 | H31: 1 | I31: 400 | J31: 0 | K31: 0 | L31: =+I31+J31-K31 -> 400 | M31: Pago | N31: MBWay

Sheet 6
A1: Análise Faturação e Despesas | Junho | TR1: JUN
TR2: Faturação | TS2: Curso | TT2: 120 | TV2: Faturação | TW2: Curso | TX2: 120
C3: Resumo de Faturação e Gastos - Junho | L3: Fluxo de Caixa | T3: Valor a Separar de Impostos
C5: Total | E5: =SUM(E6:E10) -> 2830 | G5: Total | I5: =SUM(I6:I8) -> 1983.34 | L5: Faturação | M5: =+L14 -> 2830 | N5: Recibo | O5: =+SUMIF(M16:M2599,"Pago",L16:L2499) -> 2830 | Q5: A receber | R5: =+SUMIF(M16:M2599,"Vencido",L16:L2499)+SUMIF(M16:M2599,"Pendente",L16:L2499) -> 0 | T5: IVA | U5: =+J14 -> 0
C6: =+Dados!F5 -> qEEG | E6: =+SUMIF(F16:F199994,C6,I16:I4994) -> 935 | G6: Despesas Variáveis | I6: =+SUMIF(T16:T199994,G6,U16:U4994) -> 1167.17
C7: =+Dados!F6 -> NFB | E7: =+SUMIF(F16:F199994,C7,I16:I4994) -> 455 | G7: Despesas Fixas | I7: =+SUMIF(T16:T199994,G7,U16:U4994) -> 816.17 | L7: Despesas | M7: =+W14 -> 1989.55 | N7: Pago | O7: =+SUMIF(X16:X2599,"Pago",W16:W2499) -> 1956.34 | P7: A receber | Q7: A pagamento | R7: =+SUMIF(X16:X2599,"Vencido",W16:W2499)+SUMIF(X16:X2599,"Pendente",W16:W2499) -> 0 | T7: IRS | U7: =+'IRS-2025'!F23 -> 843.14973
C8: =+Dados!F7 -> Pack NFB | E8: =+SUMIF(F16:F199994,C8,I16:I4994) -> 1440 | G8: Investimento | I8: =+SUMIF(T16:T199994,G8,U16:U4994) -> 0
C9: =+Dados!F11 -> 0 | E9: =+SUMIF(F16:F199994,C9,I16:I4994) -> 0
C10: =+Dados!F12 -> 0 | E10: =+SUMIF(F16:F199994,C10,I16:I4994) -> 0 | G10: Lucro | I10: =+E5-I5 -> 846.66
B13: Faturação | P13: Despesas
E14: TOTAL | I14: =+SUM(Fat_Jun[Base]) -> 2830 | J14: =+SUM(Fat_Jun[[IVA ]]) -> 0 | K14: =+SUM(Fat_Jun[Retenção]) -> 0 | L14: =+SUM(Fat_Jun[Total]) -> 2830 | R14: TOTAL | U14: =+SUM(Desp_Jun[Base]) -> 1983.34 | V14: =SUM(Desp_Jun[[IVA ]]) -> 6.21 | W14: =SUM(Desp_Jun[Total]) -> 1989.55
B15: Data | C15: Cliente | D15: NIF | E15: Tipologia | F15: Descrição | G15: Nº Fatura | H15: Prestação | I15: Base | J15: IVA | K15: Retenção | L15: Total | M15: Estado | N15: Método Recebimento | P15: Data | Q15: Fornecedor | R15: NIF | S15: Nº Fatura | T15: Tipo | U15: Base | V15: IVA | W15: Total | X15: Estado | Y15: Método Pagamento
B16: 45810 | C16: Ismael | D16: 230682219 | E16: Serviços | F16: NFB | G16: 46 | H16: 1 | I16: 50 | J16: 0 | K16: 0 | L16: =+I16+J16-K16 -> 50 | M16: Pago | N16: Multibanco | P16: 45809 | Q16: SS | T16: Despesas Fixas | U16: 97.11 | V16: 0 | W16: =+Desp_Jun[[#This Row],[Base]]+Desp_Jun[[#This Row],[IVA ]] -> 97.11 | X16: Pago | Y16: Transferência Bancária
B17: 45811 | C17: Paula Barbosa | D17: 203406788 | E17: Serviços | F17: qEEG | G17: 47 | H17: 1 | I17: 85 | J17: 0 | K17: 0 | L17: =+I17+J17-K17 -> 85 | M17: Pago | N17: Multibanco | P17: 45810 | Q17: ALLIANZ | T17: Despesas Variáveis | U17: 156.92 | V17: 0 | W17: =+Desp_Jun[[#This Row],[Base]]+Desp_Jun[[#This Row],[IVA ]] -> 156.92 | X17: Pago | Y17: Débito direto
B18: 45812 | C18: Alexandre | D18: 234558504 | E18: Serviços | F18: Pack NFB | G18: 48 | H18: 1 | I18: 400 | J18: 0 | K18: 0 | L18: =+I18+J18-K18 -> 400 | M18: Pago | N18: Multibanco | P18: 45811 | Q18: Renda | T18: Despesas Fixas | U18: 280 | V18: 0 | W18: =+Desp_Jun[[#This Row],[Base]]+Desp_Jun[[#This Row],[IVA ]] -> 280 | X18: Pago | Y18: Transferência Bancária
B19: 45813 | C19: Ismael | D19: 230682219 | E19: Serviços | F19: NFB | G19: 49 | H19: 1 | I19: 50 | J19: 0 | K19: 0 | L19: =+I19+J19-K19 -> 50 | M19: Pago | N19: Multibanco | P19: 45811 | Q19: Eulalia | T19: Despesas Fixas | U19: 200 | V19: 0 | W19: =+Desp_Jun[[#This Row],[Base]]+Desp_Jun[[#This Row],[IVA ]] -> 200 | X19: Pago | Y19: Transferência Bancária
B20: 45815 | C20: Pedro Fonsenca | D20: 295081457 | E20: Serviços | F20: Pack NFB | G20: 50 | H20: 1 | I20: 400 | J20: 0 | K20: 0 | L20: =+I20+J20-K20 -> 400 | M20: Pago | N20: Multibanco | P20: 45812 | Q20: TPA | T20: Despesas Fixas | U20: 27 | V20: =+Desp_Jun[[#This Row],[Base]]*0.23 -> 6.21 | W20: =+Desp_Jun[[#This Row],[Base]]+Desp_Jun[[#This Row],[IVA ]] -> 33.21 | Y20: Débito direto
B21: 45821 | C21: Joana 29C | D21: 283743719 | E21: Serviços | F21: qEEG | G21: 51 | H21: 1 | I21: 85 | J21: 0 | K21: 0 | L21: =+I21+J21-K21 -> 85 | M21: Pago | N21: Multibanco | P21: 45820 | Q21: Meta | T21: Despesas Fixas | U21: 143.02 | V21: 0 | W21: =+Desp_Jun[[#This Row],[Base]]+Desp_Jun[[#This Row],[IVA ]] -> 143.02 | X21: Pago | Y21: Débito direto
B22: 45821 | C22: Cláudia 28A | D22: 248912062 | E22: Serviços | F22: qEEG | G22: 52 | H22: 1 | I22: 85 | J22: 0 | K22: 0 | L22: =+I22+J22-K22 -> 85 | M22: Pago | N22: Multibanco | P22: 45818 | Q22: man conta | T22: Despesas Fixas | U22: 4.99 | V22: 0 | W22: =+Desp_Jun[[#This Row],[Base]]+Desp_Jun[[#This Row],[IVA ]] -> 4.99 | X22: Pago | Y22: Débito direto
B23: 45821 | C23: Ismael | D23: 230682219 | E23: Serviços | F23: NFB | G23: 53 | H23: 1 | I23: 50 | J23: 0 | K23: 0 | L23: =+I23+J23-K23 -> 50 | M23: Pago | N23: Multibanco | P23: 45818 | Q23: selo | T23: Despesas Fixas | U23: 0.2 | V23: 0 | W23: =+Desp_Jun[[#This Row],[Base]]+Desp_Jun[[#This Row],[IVA ]] -> 0.2 | X23: Pago | Y23: Débito direto
B24: 45825 | C24: Ismael | D24: 230682219 | E24: Serviços | F24: NFB | G24: 54 | H24: 1 | I24: 50 | J24: 0 | K24: 0 | L24: =+I24+J24-K24 -> 50 | M24: Pago | N24: Multibanco | P24: 45833 | Q24: banco inp | T24: Despesas Fixas | U24: 0.54 | V24: 0 | W24: =+Desp_Jun[[#This Row],[Base]]+Desp_Jun[[#This Row],[IVA ]] -> 0.54 | X24: Pago | Y24: Débito direto
B25: 45825 | C25: Carlos Rocha | D25: 193576503 | E25: Serviços | F25: qEEG | G25: 55 | H25: 1 | I25: 85 | J25: 0 | K25: 0 | L25: =+I25+J25-K25 -> 85 | M25: Pago | N25: Numerário | P25: 45833 | Q25: ChatGPT | T25: Despesas Fixas | U25: 17.41 | V25: 0 | W25: =+Desp_Jun[[#This Row],[Base]]+Desp_Jun[[#This Row],[IVA ]] -> 17.41 | X25: Pago | Y25: Débito direto
B26: 45826 | C26: Micael Silva | D26: 219466106 | E26: Serviços | F26: Pack NFB | G26: 56 | H26: 1 | I26: 40 | J26: 0 | K26: 0 | L26: =+I26+J26-K26 -> 40 | M26: Pago | N26: MBWay | P26: 45835 | Q26: Centro IPS | T26: Despesas Variáveis | U26: 300 | V26: 0 | W26: =+Desp_Jun[[#This Row],[Base]]+Desp_Jun[[#This Row],[IVA ]] -> 300 | X26: Pago | Y26: Transferência Bancária
B27: 45826 | C27: Ismael | D27: 230682219 | E27: Serviços | F27: NFB | G27: 57 | H27: 1 | I27: 50 | J27: 0 | K27: 0 | L27: =+I27+J27-K27 -> 50 | M27: Pago | N27: Multibanco | P27: 45838 | Q27: conceição | T27: Despesas Fixas | U27: 45.9 | V27: 0 | W27: =+Desp_Jun[[#This Row],[Base]]+Desp_Jun[[#This Row],[IVA ]] -> 45.9 | X27: Pago | Y27: Transferência Bancária
B28: 45826 | C28: Rui Pedro | D28: 236578499 | E28: Serviços | F28: qEEG | G28: 58 | H28: 1 | I28: 85 | J28: 0 | K28: 0 | L28: =+I28+J28-K28 -> 85 | M28: Pago | N28: Numerário | P28: 45838 | Q28: sanotecnica | T28: Despesas Variáveis | U28: 710.25 | V28: 0 | W28: =+Desp_Jun[[#This Row],[Base]]+Desp_Jun[[#This Row],[IVA ]] -> 710.25 | X28: Pago | Y28: Transferência Bancária
B29: 45826 | C29: Benedita Ribeiro | D29: 289723299 | E29: Serviços | F29: qEEG | G29: 59 | H29: 1 | I29: 85 | J29: 0 | K29: 0 | L29: =+I29+J29-K29 -> 85 | M29: Pago | N29: Multibanco
B30: 45826 | C30: Cristina Castro | D30: 199956677 | E30: Serviços | F30: qEEG | G30: 60 | H30: 1 | I30: 85 | J30: 0 | K30: 0 | L30: =+I30+J30-K30 -> 85 | M30: Pago | N30: Multibanco
B31: 45831 | C31: Maria Bertilia | D31: 180062468 | E31: Serviços | F31: qEEG | G31: 61 | H31: 1 | I31: 85 | J31: 0 | K31: 0 | L31: =+I31+J31-K31 -> 85 | M31: Pago | N31: Multibanco
B32: 45832 | C32: Joana 29C | D32: 283743719 | E32: Serviços | F32: Pack NFB | G32: 62 | H32: 1 | I32: 400 | J32: 0 | K32: 0 | L32: =+I32+J32-K32 -> 400 | M32: Pago | N32: Multibanco
B33: 45832 | C33: Ismael | D33: 230682219 | E33: Serviços | F33: NFB | G33: 63 | H33: 1 | I33: 50 | J33: 0 | K33: 0 | L33: =+I33+J33-K33 -> 50 | M33: Pago | N33: Multibanco
B34: 45834 | C34: Cláudia 28A | D34: 248912062 | E34: Serviços | F34: NFB | G34: 64 | H34: 1 | I34: 50 | J34: 0 | K34: 0 | L34: =+I34+J34-K34 -> 50 | M34: Pago | N34: Multibanco
B35: 45833 | C35: Rute | D35: 0 | E35: Serviços | F35: qEEG | H35: 1 | I35: 85 | J35: 0 | K35: 0 | L35: =+I35+J35-K35 -> 85 | M35: Pago | N35: Multibanco
B36: 45804 | C36: Carlos Rocha | D36: 193576503 | E36: Serviços | F36: Pack NFB | G36: 66 | H36: 1 | I36: 200 | J36: 0 | K36: 0 | L36: =+I36+J36-K36 -> 200 | M36: Pago | N36: Numerário
B37: 45804 | C37: Cláudia 28A | D37: 248912062 | E37: Serviços | F37: NFB | G37: 65 | H37: 1 | I37: 50 | J37: 0 | K37: 0 | L37: =+I37+J37-K37 -> 50 | M37: Pago | N37: Multibanco
B38: 45807 | C38: Cristina Castro | D38: 199956677 | E38: Serviços | F38: NFB | G38: 67 | H38: 1 | I38: 55 | J38: 0 | K38: 0 | L38: =+I38+J38-K38 -> 55 | M38: Pago | N38: Multibanco
B39: 45807 | C39: Eduardo 35C | D39: 287799204 | E39: Serviços | F39: qEEG | G39: 68 | H39: 1 | I39: 85 | J39: 0 | K39: 0 | L39: =+I39+J39-K39 -> 85 | M39: Pago | N39: Numerário
B40: 45807 | C40: Manuela 36A | D40: 192025821 | E40: Serviços | F40: qEEG | G40: 69 | H40: 1 | I40: 85 | J40: 0 | K40: 0 | L40: =+I40+J40-K40 -> 85 | M40: Pago | N40: Numerário

Sheet 7
A1: Análise Faturação e Despesas | Julho | TR1: JUL
TR2: Faturação | TS2: Curso | TT2: 671 | TV2: Faturação | TW2: Curso | TX2: 671
C3: Resumo de Faturação e Gastos - Julho | L3: Fluxo de Caixa | T3: Valor a Separar de Impostos
C5: Total | E5: =SUM(E6:E10) -> 6620 | G5: Total | I5: =SUM(I6:I8) -> 0 | L5: Faturação | M5: =+L14 -> 6620 | N5: Recibo | O5: =+SUMIF(M16:M2599,"Pago",L16:L2499) -> 6620 | Q5: A receber | R5: =+SUMIF(M16:M2599,"Vencido",L16:L2499)+SUMIF(M16:M2599,"Pendente",L16:L2499) -> 0 | T5: IVA | U5: =+J14 -> 0
C6: =+Dados!F5 -> qEEG | E6: =+SUMIF(F16:F199994,C6,I16:I4994) -> 1127 | G6: Despesas Variáveis | I6: =+SUMIF(T16:T199994,G6,U16:U4994) -> 0
C7: =+Dados!F6 -> NFB | E7: =+SUMIF(F16:F199994,C7,I16:I4994) -> 1245 | G7: Despesas Fixas | I7: =+SUMIF(T16:T199994,G7,U16:U4994) -> 0 | L7: Despesas | M7: =+W14 -> 0 | N7: Pago | O7: =+SUMIF(X16:X2599,"Pago",W16:W2499) -> 0 | P7: A receber | Q7: A pagamento | R7: =+SUMIF(X16:X2599,"Vencido",W16:W2499)+SUMIF(X16:X2599,"Pendente",W16:W2499) -> 0 | T7: IRS | U7: =+'IRS-2025'!F23 -> 843.14973
C8: =+Dados!F7 -> Pack NFB | E8: =+SUMIF(F16:F199994,C8,I16:I4994) -> 4248 | G8: Investimento | I8: =+SUMIF(T16:T199994,G8,U16:U4994) -> 0
C9: =+Dados!F11 -> 0 | E9: =+SUMIF(F16:F199994,C9,I16:I4994) -> 0
C10: =+Dados!F12 -> 0 | E10: =+SUMIF(F16:F199994,C10,I16:I4994) -> 0 | G10: Lucro | I10: =+E5-I5 -> 6620
B13: Faturação | P13: Despesas
E14: TOTAL | I14: =+SUM(Fat_Jul[Base]) -> 6620 | J14: =+SUM(Fat_Jul[[IVA ]]) -> 0 | K14: =+SUM(Fat_Jul[Retenção]) -> 0 | L14: =+SUM(Fat_Jul[Total]) -> 6620 | R14: TOTAL | U14: =+SUM(Desp_Jul[Base]) -> 0 | V14: =SUM(Desp_Jul[[IVA ]]) -> 0 | W14: =SUM(Desp_Jul[Total]) -> 0
B15: Data | C15: Cliente | D15: NIF | E15: Tipologia | F15: Descrição | G15: Nº Fatura | H15: Prestação | I15: Base | J15: IVA | K15: Retenção | L15: Total | M15: Estado | N15: Método Recebimento | P15: Data | Q15: Fornecedor | R15: NIF | S15: Nº Fatura | T15: Tipo | U15: Base | V15: IVA | W15: Total | X15: Estado | Y15: Método Pagamento
B16: 45839 | C16: Ismael | D16: 230682219 | E16: Serviços | F16: NFB | G16: 70 | H16: 1 | I16: 50 | J16: 0 | K16: 0 | L16: =+I16+J16-K16 -> 50 | M16: Pago | N16: Multibanco | V16: =+Desp_Jul[[#This Row],[Base]]*0.23 -> 0 | W16: =+Desp_Jul[[#This Row],[Base]]+Desp_Jul[[#This Row],[IVA ]] -> 0
B17: 45839 | C17: Cristina Castro | D17: 199956677 | E17: Serviços | F17: NFB | G17: 71 | H17: 1 | I17: 55 | J17: 0 | K17: 0 | L17: =+I17+J17-K17 -> 55 | M17: Pago | N17: Multibanco | V17: =+Desp_Jul[[#This Row],[Base]]*0.23 -> 0 | W17: =+Desp_Jul[[#This Row],[Base]]+Desp_Jul[[#This Row],[IVA ]] -> 0
B18: 45841 | C18: Ismael | D18: 230682219 | E18: Serviços | F18: NFB | G18: 73 | H18: 1 | I18: 50 | J18: 0 | K18: 0 | L18: =+I18+J18-K18 -> 50 | M18: Pago | N18: Multibanco | V18: =+Desp_Jul[[#This Row],[Base]]*0.23 -> 0 | W18: =+Desp_Jul[[#This Row],[Base]]+Desp_Jul[[#This Row],[IVA ]] -> 0
B19: 45841 | C19: Cláudia 28A | D19: 248912062 | E19: Serviços | F19: NFB | G19: 74 | H19: 1 | I19: 50 | J19: 0 | K19: 0 | L19: =+I19+J19-K19 -> 50 | M19: Pago | N19: Multibanco | V19: =+Desp_Jul[[#This Row],[Base]]*0.23 -> 0 | W19: =+Desp_Jul[[#This Row],[Base]]+Desp_Jul[[#This Row],[IVA ]] -> 0
B20: 45841 | C20: Benedita | D20: 289723299 | E20: Serviços | F20: Pack NFB | G20: 75 | H20: 1 | I20: 400 | J20: 0 | K20: 0 | L20: =+I20+J20-K20 -> 400 | M20: Pago | N20: Numerário | V20: =+Desp_Jul[[#This Row],[Base]]*0.23 -> 0 | W20: =+Desp_Jul[[#This Row],[Base]]+Desp_Jul[[#This Row],[IVA ]] -> 0
B21: 45842 | C21: Manuela | D21: 0 | E21: Serviços | F21: Pack NFB | H21: 1 | I21: 308 | J21: 0 | K21: 0 | L21: =+I21+J21-K21 -> 308 | M21: Pago | N21: Numerário | V21: =+Desp_Jul[[#This Row],[Base]]*0.23 -> 0 | W21: =+Desp_Jul[[#This Row],[Base]]+Desp_Jul[[#This Row],[IVA ]] -> 0
B22: 45842 | C22: Rute | D22: 230470785 | E22: Serviços | F22: Pack NFB | G22: 76 | H22: 1 | I22: 400 | J22: 0 | K22: 0 | L22: =+I22+J22-K22 -> 400 | M22: Pago | N22: Multibanco | V22: =+Desp_Jul[[#This Row],[Base]]*0.23 -> 0 | W22: =+Desp_Jul[[#This Row],[Base]]+Desp_Jul[[#This Row],[IVA ]] -> 0
B23: 45841 | C23: João Montenegro | D23: 180062450 | E23: Serviços | F23: qEEG | G23: 72 | H23: 1 | I23: 85 | J23: 0 | K23: 0 | L23: =+I23+J23-K23 -> 85 | M23: Pago | N23: Numerário
B24: 45842 | C24: Pedro Fonseca | D24: 295081457 | E24: Serviços | F24: Pack NFB | G24: 77 | H24: 1 | I24: 400 | J24: 0 | K24: 0 | L24: =+I24+J24-K24 -> 400 | M24: Pago | N24: Multibanco
B25: 45845 | C25: António | D25: 178479691 | E25: Serviços | F25: Pack NFB | G25: 78 | H25: 1 | I25: 50 | J25: 0 | K25: 0 | L25: =+I25+J25-K25 -> 50 | M25: Pago | N25: Numerário
B26: 45845 | C26: Cristina Castro | D26: 199956677 | E26: Serviços | F26: NFB | G26: 82 | H26: 2 | I26: 110 | J26: 0 | K26: 0 | L26: =+I26+J26-K26 -> 110 | M26: Pago | N26: Multibanco
B27: 45845 | C27: Cláudia 28A | D27: 248912062 | E27: Serviços | F27: NFB | G27: 80 | H27: 1 | I27: 50 | J27: 0 | K27: 0 | L27: =+I27+J27-K27 -> 50 | M27: Pago | N27: Multibanco
B28: 45845 | C28: João Pedro | D28: 261357077 | E28: Serviços | F28: qEEG | G28: 81 | H28: 1 | I28: 85 | J28: 0 | K28: 0 | L28: =+I28+J28-K28 -> 85 | M28: Pago | N28: Multibanco
B29: 45846 | C29: Ismael | D29: 230682219 | E29: Serviços | F29: NFB | G29: 83 | H29: 1 | I29: 50 | J29: 0 | K29: 0 | L29: =+I29+J29-K29 -> 50 | M29: Pago | N29: Multibanco
B30: 45847 | C30: Cláudia 28A | D30: 248912062 | E30: Serviços | F30: NFB | G30: 84 | H30: 1 | I30: 50 | J30: 0 | K30: 0 | L30: =+I30+J30-K30 -> 50 | M30: Pago | N30: Multibanco
B31: 45847 | C31: Eduardo 35C | D31: 0 | E31: Serviços | F31: Pack NFB | H31: 1 | I31: 308 | J31: 0 | K31: 0 | L31: =+I31+J31-K31 -> 308 | M31: Pago | N31: Numerário
B32: 45848 | C32: Ismael | D32: 230682219 | E32: Serviços | F32: NFB | G32: 85 | H32: 1 | I32: 50 | J32: 0 | K32: 0 | L32: =+I32+J32-K32 -> 50 | M32: Pago | N32: Multibanco
B33: 45848 | C33: Madalena | D33: 0 | E33: Serviços | F33: qEEG | H33: 1 | I33: 65 | J33: 0 | K33: 0 | L33: =+I33+J33-K33 -> 65 | M33: Pago | N33: Numerário
B34: 45848 | C34: Micael Silva | D34: 219466106 | E34: Serviços | F34: Pack NFB | G34: 87 | H34: 1 | I34: 400 | J34: 0 | K34: 0 | L34: =+I34+J34-K34 -> 400 | M34: Pago | N34: MBWay
B35: 45849 | C35: Fátima 40A | D35: 197574882 | E35: Serviços | F35: qEEG | G35: 88 | H35: 1 | I35: 85 | J35: 0 | K35: 0 | L35: =+I35+J35-K35 -> 85 | M35: Pago | N35: Multibanco
B36: 45850 | C36: Cláudia 28A | D36: 248912062 | E36: Serviços | F36: NFB | G36: 89 | H36: 1 | I36: 50 | J36: 0 | K36: 0 | L36: =+I36+J36-K36 -> 50 | M36: Pago | N36: Multibanco
B37: 45850 | C37: Cristina Castro | D37: 199956677 | E37: Serviços | F37: NFB | G37: 90 | H37: 1 | I37: 55 | J37: 0 | K37: 0 | L37: =+I37+J37-K37 -> 55 | M37: Pago | N37: Multibanco
B38: 45852 | C38: André 41A | D38: 224095773 | E38: Serviços | F38: qEEG | G38: 91 | H38: 1 | I38: 85 | J38: 0 | K38: 0 | L38: =+I38+J38-K38 -> 85 | M38: Pago | N38: Numerário
B39: 45853 | C39: Ismael | D39: 230682219 | E39: Serviços | F39: NFB | G39: 92 | H39: 1 | I39: 50 | J39: 0 | K39: 0 | L39: =+I39+J39-K39 -> 50 | M39: Pago | N39: Multibanco
B40: 45854 | C40: Fernanda 42A | D40: 201913410 | E40: Serviços | F40: qEEG | G40: 93 | H40: 1 | I40: 85 | J40: 0 | K40: 0 | L40: =+I40+J40-K40 -> 85 | M40: Pago | N40: Numerário
B41: 45855 | C41: Ismael | D41: 230682219 | E41: Serviços | F41: NFB | G41: 94 | H41: 1 | I41: 50 | J41: 0 | K41: 0 | L41: =+I41+J41-K41 -> 50 | M41: Pago | N41: Multibanco
B42: 45855 | C42: Domingos 43A | D42: 0 | E42: Serviços | F42: qEEG | H42: 1 | I42: 85 | J42: 0 | K42: 0 | L42: =+I42+J42-K42 -> 85 | M42: Pago | N42: Numerário
B43: 45855 | C43: Madalena | D43: 0 | E43: Serviços | F43: Pack NFB | H43: 1 | I43: 308 | J43: 0 | K43: 0 | L43: =+I43+J43-K43 -> 308 | M43: Pago | N43: Numerário
...

Sheet 8
A1: Análise Faturação e Despesas | Agosto | TR1: AGO
TR2: Faturação | TS2: Curso | TT2: 315 | TV2: Faturação | TW2: Curso | TX2: 315
C3: Resumo de Faturação e Gastos - Agosto | L3: Fluxo de Caixa | T3: Valor a Separar de Impostos
C5: Total | E5: =SUM(E6:E10) -> 2422.5 | G5: Total | I5: =SUM(I6:I8) -> 0 | L5: Faturação | M5: =+L14 -> 2422.5 | N5: Recibo | O5: =+SUMIF(M16:M2599,"Pago",L16:L2499) -> 2422.5 | Q5: A receber | R5: =+SUMIF(M16:M2599,"Vencido",L16:L2499)+SUMIF(M16:M2599,"Pendente",L16:L2499) -> 0 | T5: IVA | U5: =+J14 -> 0
C6: =+Dados!F5 -> qEEG | E6: =+SUMIF(F16:F199994,C6,I16:I4994) -> 202.5 | G6: Despesas Variáveis | I6: =+SUMIF(T16:T199994,G6,U16:U4994) -> 0
C7: =+Dados!F6 -> NFB | E7: =+SUMIF(F16:F199994,C7,I16:I4994) -> 404 | G7: Despesas Fixas | I7: =+SUMIF(T16:T199994,G7,U16:U4994) -> 0 | L7: Despesas | M7: =+W14 -> 0 | N7: Pago | O7: =+SUMIF(X16:X2599,"Pago",W16:W2499) -> 0 | P7: A receber | Q7: A pagamento | R7: =+SUMIF(X16:X2599,"Vencido",W16:W2499)+SUMIF(X16:X2599,"Pendente",W16:W2499) -> 0 | T7: IRS | U7: =+'IRS-2025'!F23 -> 843.14973
C8: =+Dados!F7 -> Pack NFB | E8: =+SUMIF(F16:F199994,C8,I16:I4994) -> 1816 | G8: Investimento | I8: =+SUMIF(T16:T199994,G8,U16:U4994) -> 0
C9: =+Dados!F11 -> 0 | E9: =+SUMIF(F16:F199994,C9,I16:I4994) -> 0
C10: =+Dados!F12 -> 0 | E10: =+SUMIF(F16:F199994,C10,I16:I4994) -> 0 | G10: Lucro | I10: =+E5-I5 -> 2422.5
B13: Faturação | P13: Despesas
E14: TOTAL | I14: =+SUM(Fat_Ago[Base]) -> 2422.5 | J14: =+SUM(Fat_Ago[[IVA ]]) -> 0 | K14: =+SUM(Fat_Ago[Retenção]) -> 0 | L14: =+SUM(Fat_Ago[Total]) -> 2422.5 | R14: TOTAL | U14: =+SUM(Desp_Ago[Base]) -> 0 | V14: =SUM(Desp_Ago[[IVA ]]) -> 0 | W14: =SUM(Desp_Ago[Total]) -> 0
B15: Data | C15: Cliente | D15: NIF | E15: Tipologia | F15: Descrição | G15: Nº Fatura | H15: Prestação | I15: Base | J15: IVA | K15: Retenção | L15: Total | M15: Estado | N15: Método Recebimento | P15: Data | Q15: Fornecedor | R15: NIF | S15: Nº Fatura | T15: Tipo | U15: Base | V15: IVA | W15: Total | X15: Estado | Y15: Método Pagamento
B16: 45871 | C16: Cristina 32A | D16: 199956677 | E16: Serviços | F16: NFB | G16: 113 | H16: 1 | I16: 55 | J16: 0 | K16: 0 | L16: =+I16+J16-K16 -> 55 | M16: Pago | N16: Multibanco | V16: =+Desp_Ago[[#This Row],[Base]]*0.23 -> 0 | W16: =+Desp_Ago[[#This Row],[Base]]+Desp_Ago[[#This Row],[IVA ]] -> 0
B17: 45873 | C17: Maria Ines 50C | D17: 283095083 | E17: Serviços | F17: qEEG | G17: 114 | H17: 1 | I17: 85 | J17: 0 | K17: 0 | L17: =+I17+J17-K17 -> 85 | M17: Pago | N17: Multibanco | V17: =+Desp_Ago[[#This Row],[Base]]*0.23 -> 0 | W17: =+Desp_Ago[[#This Row],[Base]]+Desp_Ago[[#This Row],[IVA ]] -> 0
B18: 45873 | C18: Gonçalo 51C | D18: 276603796 | E18: Serviços | F18: qEEG | G18: 115 | H18: 1 | I18: 42.5 | J18: 0 | K18: 0 | L18: =+I18+J18-K18 -> 42.5 | M18: Pago | N18: Numerário | V18: =+Desp_Ago[[#This Row],[Base]]*0.23 -> 0 | W18: =+Desp_Ago[[#This Row],[Base]]+Desp_Ago[[#This Row],[IVA ]] -> 0
B19: 45873 | C19: Rute 34A | D19: 230470785 | E19: Serviços | F19: Pack NFB | G19: 116 | H19: 1 | I19: 400 | J19: 0 | K19: 0 | L19: =+I19+J19-K19 -> 400 | M19: Pago | N19: Multibanco | V19: =+Desp_Ago[[#This Row],[Base]]*0.23 -> 0 | W19: =+Desp_Ago[[#This Row],[Base]]+Desp_Ago[[#This Row],[IVA ]] -> 0
B20: 45876 | C20: Ismael 21A | D20: 230682219 | E20: Serviços | F20: NFB | G20: 117 | H20: 1 | I20: 50 | J20: 0 | K20: 0 | L20: =+I20+J20-K20 -> 50 | M20: Pago | N20: Multibanco | V20: =+Desp_Ago[[#This Row],[Base]]*0.23 -> 0 | W20: =+Desp_Ago[[#This Row],[Base]]+Desp_Ago[[#This Row],[IVA ]] -> 0
B21: 45876 | C21: Cristina 32A | D21: 199956677 | E21: Serviços | F21: NFB | G21: 118 | H21: 1 | I21: 55 | J21: 0 | K21: 0 | L21: =+I21+J21-K21 -> 55 | M21: Pago | N21: Multibanco | V21: =+Desp_Ago[[#This Row],[Base]]*0.23 -> 0 | W21: =+Desp_Ago[[#This Row],[Base]]+Desp_Ago[[#This Row],[IVA ]] -> 0
B22: 45875 | C22: 37A João | D22: 0 | E22: Serviços | F22: NFB | H22: 1 | I22: 42 | J22: 0 | K22: 0 | L22: =+I22+J22-K22 -> 42 | M22: Pago | N22: Numerário | V22: =+Desp_Ago[[#This Row],[Base]]*0.23 -> 0 | W22: =+Desp_Ago[[#This Row],[Base]]+Desp_Ago[[#This Row],[IVA ]] -> 0
B23: 45881 | C23: Benedita 31C | D23: 289723299 | E23: Serviços | F23: Pack NFB | G23: 119 | H23: 1 | I23: 400 | J23: 0 | K23: 0 | L23: 400 | M23: Pago | N23: Numerário
B24: 45881 | C24: Ismael 21A | D24: 230682219 | E24: Serviços | F24: NFB | G24: 120 | H24: 1 | I24: 50 | J24: 0 | K24: 0 | L24: =+I24+J24-K24 -> 50 | M24: Pago | N24: Multibanco
B25: 45882 | C25: Lurdes 400 | D25: 0 | E25: Serviços | F25: Pack NFB | H25: 1 | I25: 308 | J25: 0 | K25: 0 | L25: =+I25+J25-K25 -> 308 | M25: Pago | N25: Numerário
B26: 45883 | C26: 37A João | D26: 0 | E26: Serviços | F26: NFB | H26: 1 | I26: 42 | J26: 0 | K26: 0 | L26: =+I26+J26-K26 -> 42 | M26: Pago | N26: Numerário
B27: 45883 | C27: 36A Manuela | D27: 0 | E27: Serviços | F27: Pack NFB | H27: 1 | I27: 400 | J27: 0 | K27: 0 | L27: =+I27+J27-K27 -> 400 | M27: Pago | N27: Numerário
B28: 45884 | C28: 35C Eduardo | D28: 0 | E28: Serviços | F28: Pack NFB | H28: 1 | I28: 308 | J28: 0 | K28: 0 | L28: =+I28+J28-K28 -> 308 | M28: Pago | N28: Numerário
B29: 45885 | C29: Dinis 52C | D29: 293713545 | E29: Serviços | F29: qEEG | G29: 121 | H29: 1 | I29: 75 | J29: 0 | K29: 0 | L29: =+I29+J29-K29 -> 75 | M29: Pago | N29: Numerário
B30: 45889 | C30: 32A Cristina | D30: 199956677 | E30: Serviços | F30: NFB | G30: 122 | H30: 2 | I30: 110 | J30: 0 | K30: 0 | L30: =+I30+J30-K30 -> 110 | M30: Pago | N30: Multibanco
B31: 45889 | J31: =Fat_Ago[[#This Row],[Base]]*0.23 -> 0 | L31: =+I31+J31-K31 -> 0

Sheet 9
A1: Análise Faturação e Despesas | Setembro | TR1: SET
TR2: Faturação | TS2: Curso | TT2: 0 | TV2: Faturação | TW2: Curso | TX2: 0
C3: Resumo de Faturação e Gastos - Setembro | L3: Fluxo de Caixa | T3: Valor a Separar de Impostos
